<robot name="myCar">

    <!-- 注意： 在设置偏移量 origin 时，要从物体的中心开始计算偏移距离 -->

    <!-- base_footprint 为支撑的关节，能防止物体沉于地下 -->
    <link name="base_footprint">
        <visual>
            <geometry>
                <sphere radius="0.001" />
            </geometry>
            <origin xyz="0 0 0" rpy="0 0 0" />
            <material name="footprint_color">
                <color rgba="0 1 0 0.4" />
            </material>
        </visual>
    </link>

    <!-- 底盘 -->
    <link name="base_link">
        <visual>
            <geometry>
                <box size="0.3 0.5 0.4" />
            </geometry>
            <origin xyz="0 0 0" rpy="0 0 0" />
            <material name="car_color">
                <color rgba="0 1 0 0.4" />
            </material>
        </visual>
    </link>

    <!-- 摄像头 -->
    <link name="camera">
        <visual>
            <geometry>
                <box size="0.05 0.05 0.1" />
            </geometry>
            <origin xyz="0 0 0" rpy="0 0 0" />
            <material name="car_color">
                <color rgba="1 0 0 0.4" />
            </material>
        </visual>
    </link>

    <!-- 连接 base_footprint 和底盘，起到支撑作用 -->
    <joint name="base2foot" type="fixed">
        <parent link="base_footprint" />
        <child link="base_link" />
        <origin xyz="0 0 0.2" rpy="0 0 0" />
    </joint>

    <!-- 连接摄像头和底盘 -->
    <joint name="camera2base" type="continuous">
        <parent link="base_link" />
        <child link="camera" />
        <origin xyz="0.125 0 0.25" rpy="0 0 0" />
        <axis xyz="0 0 1" />
    </joint>
</robot>
